Workbook

Sheet Consolidated Data
A1: Row ID | B1: Source (Person) | C1: Source Document | D1: Source Date | E1: Community / Company / Model | F1: Operator | G1: Location | H1: Community Type / Model | I1: Villa / Cottage Count | J1: Pricing (as reported) | K1: Monthly Fee Low ($) | L1: Monthly Fee High ($) | M1: Entry Fee? | N1: Transportation | O1: Life Enrichment / Campus Amenities | P1: Culinary / Dining | Q1: Housekeeping / Laundry & Linen | R1: Wellness / Fitness / Health | S1: Emergency / Safety / Security | T1: Maintenance (Interior / Exterior / Grounds) | U1: Utilities / Taxes / Insurance | V1: Additional / À La Carte / Concierge | W1: Residence Features (garage, W/D, patio, etc.) | X1: Notes / Flags | Y1: Sub-market / Map Reference (Lopez) | Z1: Year Opened | AA1: Tier: Transportation | AB1: Tier: Life Enrichment / Campus Amenities | AC1: Tier: Culinary / Dining | AD1: Tier: Housekeeping / Laundry & Linen | AE1: Tier: Wellness / Fitness / Health | AF1: Tier: Emergency / Safety / Security | AG1: Tier: Maintenance (Interior / Exterior / Grounds) | AH1: Tier: Utilities / Taxes / Insurance | AI1: Tier: Additional / À La Carte / Concierge
A2: 1 | B2: Laura Lopez | C2: Word doc: Villa Study Scratch List (Updated Oct 2023) | D2: Oct 2023 (doc); received by email Sept 2026 | E2: Friendship Village Kalamazoo | F2: Life Care Services | G2: Kalamazoo, MI | H2: CCRC | I2: 50 villas | J2: 2 Bed/2 Bath, 1300 sq ft: $2926; Entry Fee: $233,130 - $369,900 | 3 Bed/2 Bath, 1500 sq ft: $3346; EF: $261,530 - $415,000 | 3 Bed/2.5 bath, 1800 sq ft: $4006; EF: $304,990 - $483,900 | K2: 2926 | L2: 4006 | M2: Yes | N2: Transportation | O2: Main Campus amenities (pool; gym w/ trainer; chaplain; café; general store) | Q2: Bi-Weekly Housekeeping | R2: (via campus amenities) Main Campus amenities (pool; gym w/ trainer; chaplain; café; general store) | S2: Emergency call system | U2: All utilities, including cable | W2: In-unit washer/dryer; 1.5 car attached garage | Y2: Kalamazoo Acquisition – Fountains at Bronson Place | AA2: Included | AB2: Included | AC2: Not stated | AD2: Included | AE2: Included | AF2: Included | AG2: Not stated | AH2: Included | AI2: Not stated
A3: 2 | B3: Laura Lopez | C3: Word doc: Villa Study Scratch List (Updated Oct 2023) | D3: Oct 2023 (doc); received by email Sept 2026 | E3: Wittenberg Village | F3: Lutheran Life Communities | G3: Crown Point, IN | H3: CCRC | I3: 47 Villas | M3: CCRC (entry fee not stated) | N3: Transportation | O3: Campus amenities (chapel/chaplain; country store; fitness center | P3: One meal per day | Q3: B-weekly housekeeping & flat linen service | R3: (via campus amenities) Campus amenities (chapel/chaplain; country store; fitness center | S3: Emergency call system | U3: Basic cable & Wi-Fi | W3: Many with a garage | Y3: NW Indiana | Z3: 1974 | AA3: Included | AB3: Included | AC3: Included | AD3: Included | AE3: Included | AF3: Included | AG3: Not stated | AH3: Included | AI3: Not stated
A4: 3 | B4: Laura Lopez | C4: Word doc: Villa Study Scratch List (Updated Oct 2023) | D4: Oct 2023 (doc); received by email Sept 2026 | E4: The Moorings of Arlington Heights | F4: Presbyterian Homes | G4: Arlington Heights, IL | H4: CCRC | I4: 72 Villas (1276 – 2036 sq ft) | J4: $4620 for a villa; Entrance Fee: $299,600 | K4: 4620 | L4: 4620 | M4: Yes | N4: Transportation | O4: Campus amenities (pool; fitness center) | Q4: Weekly Housekeeping | R4: (via campus amenities) Campus amenities (pool; fitness center) | S4: Emergency call system | V4: $490 per month “discretionary dollar account” | W4: Attached two-car garage; In-unit washer/dryer; Some include basements | Y4: NW Chicago New Dev – Schaumburg add Comps | Z4: 1989 | AA4: Included | AB4: Included | AC4: Not stated | AD4: Included | AE4: Included | AF4: Included | AG4: Not stated | AH4: Not stated | AI4: Included
A5: 4 | B5: Laura Lopez | C5: Word doc: Villa Study Scratch List (Updated Oct 2023) | D5: Oct 2023 (doc); received by email Sept 2026 | E5: Newcastle Place | F5: Life Care Services, LLC | G5: Mequon, WI | H5: CCRC | I5: 29 Villas (1718 – 1982 sq ft) | M5: CCRC (entry fee not stated) | Q5: Bi-weekly housekeeping & linen service | U5: All utilities including cable & Wi-Fi | W5: Attached two-car garage; 2 Bed/2 Bath; In-unit washer/dryer | Y5: Wright House, Mequon WI | Z5: 2003 | AA5: Not stated | AB5: Not stated | AC5: Not stated | AD5: Included | AE5: Not stated | AF5: Not stated | AG5: Not stated | AH5: Included | AI5: Not stated
A6: 5 | B6: Laura Lopez | C6: Word doc: Villa Study Scratch List (Updated Oct 2023) | D6: Oct 2023 (doc); received by email Sept 2026 | E6: Crown Point Christian Village | F6: Christian Homes, Inc. | G6: Crown Point, IN | H6: Villa, AL, MC | I6: 20 Villas (up to 1614 sq ft) | M6: Not stated | P6: Weekly continental breakfast | Q6: Bi-weekly housekeeping | U6: Paid utilities including basic cable & Wi-Fi | W6: 2 Bed/2 Bath; In-unit washer/dryer; Attached one-car garage | Y6: NW Indiana | Z6: 1993 | AA6: Not stated | AB6: Not stated | AC6: Included | AD6: Included | AE6: Not stated | AF6: Not stated | AG6: Not stated | AH6: Included | AI6: Not stated
A7: 6 | B7: Laura Lopez | C7: Word doc: Villa Study Scratch List (Updated Oct 2023) | D7: Oct 2023 (doc); received by email Sept 2026 | E7: Friendship Village of Schaumburg | F7: Friendship Senior Options | G7: Schaumburg, IL | H7: CCRC | I7: 28 Villas (1350 – 1750 sq ft) | M7: CCRC (entry fee not stated) | W7: Attached garage; In-unit washer/dryer w/ laundry room | Y7: NW Chicago New Dev – Schaumburg add Comps | Z7: 1977 | AA7: Not stated | AB7: Not stated | AC7: Not stated | AD7: Not stated | AE7: Not stated | AF7: Not stated | AG7: Not stated | AH7: Not stated | AI7: Not stated
A8: 7 | B8: Laura Lopez | C8: Word doc: Villa Study Scratch List (Updated Oct 2023) | D8: Oct 2023 (doc); received by email Sept 2026 | E8: Sunrise of Olympia Fields | F8: Sunrise Senior Living | G8: Olympia Fields, IL | H8: Villa, IL, AL | I8: 32 Villas | M8: Not stated | Y8: Frankfort, IL (New Dev) | Z8: 1999 | AA8: Not stated | AB8: Not stated | AC8: Not stated | AD8: Not stated | AE8: Not stated | AF8: Not stated | AG8: Not stated | AH8: Not stated | AI8: Not stated
A9: 8 | B9: Laura Lopez | C9: Word doc: Villa Study Scratch List (Updated Oct 2023) | D9: Oct 2023 (doc); received by email Sept 2026 | E9: Smith Crossing | F9: Smith Senior Living Communities | G9: Orland Park, IL | H9: CCRC | I9: 10 Villas (1506 – 1809 sq ft) | M9: CCRC (entry fee not stated) | O9: Campus amenities (fitness center w/ exercise physiologist; movie theater; etc.) | R9: (via campus amenities) Campus amenities (fitness center w/ exercise physiologist; movie theater; etc.) | W9: Attached two-car garage; In-unit washer/dryer; Enclosed porch or screened patio | Y9: Frankfort, IL (New Dev) | Z9: 2004 | AA9: Not stated | AB9: Included | AC9: Not stated | AD9: Not stated | AE9: Included | AF9: Not stated | AG9: Not stated | AH9: Not stated | AI9: Not stated
A10: 9 | B10: Laura Lopez | C10: Word doc: Villa Study Scratch List (Updated Oct 2023) | D10: Oct 2023 (doc); received by email Sept 2026 | E10: Briar Creek Independent Senior Living Community | F10: Warmus Senior Living | G10: Uniontown, OH | H10: Villa & IL | I10: 36 Villas | M10: Not stated | O10: Campus amenities (gym, movie theater, coffee bar, etc.) | Q10: Housekeeping | R10: (via campus amenities) Campus amenities (gym, movie theater, coffee bar, etc.) | T10: Maintenance | Y10: Lancaster-Jackson Twp OH Danbury New Devs (Jackson) | Z10: 2017 | AA10: Not stated | AB10: Included | AC10: Not stated | AD10: Included | AE10: Included | AF10: Not stated | AG10: Included | AH10: Not stated | AI10: Not stated
A11: 10 | B11: Laura Lopez | C11: Word doc: Villa Study Scratch List (Updated Oct 2023) | D11: Oct 2023 (doc); received by email Sept 2026 | E11: Primrose Retirement Community of Lancaster | F11: Primrose Retirement Communities | G11: Lancaster, OH | H11: Villa, IL, AL & MC | I11: 10 Villas (1594 sq ft) | M11: Not stated | O11: Campus amenities (chapel, wellness center, ice cream parlor) | P11: Daily meal | R11: (via campus amenities) Campus amenities (chapel, wellness center, ice cream parlor) | S11: Emergency call system; Emergency call system | U11: All utilities including cable and internet | W11: Attached garage; In-unit washer/dryer | Y11: Lancaster-Jackson Twp OH Danbury New Devs (Lancaster) | Z11: 2007 | AA11: Not stated | AB11: Included | AC11: Included | AD11: Not stated | AE11: Included | AF11: Included | AG11: Not stated | AH11: Included | AI11: Not stated
A12: 11 | B12: Laura Lopez | C12: Word doc: Villa Study Scratch List (Updated Oct 2023) | D12: Oct 2023 (doc); received by email Sept 2026 | E12: Concordia Village | F12: Lutheran Senior Services | G12: Springfield, IL | H12: CCRC | I12: 23 Villas (1895 sq ft) | M12: CCRC (entry fee not stated) | N12: Transportation services | O12: Campus amenities (Chapel w/ chaplain; art studio; village market; fitness center w/ indoor pool; movie theater) | Q12: Scheduled housekeeping services | R12: (via campus amenities) Campus amenities (Chapel w/ chaplain; art studio; village market; fitness center w/ indoor pool; movie theater) | U12: “Many utility costs included” | W12: 3 Bed/2 Bath; In-unit washer/dryer; Optional patio; Attached two-car garage | Y12: Illinois Holiday Acquisitions (Springfield) | Z12: 1995 | AA12: Included | AB12: Included | AC12: Not stated | AD12: Included | AE12: Included | AF12: Not stated | AG12: Not stated | AH12: Included | AI12: Not stated
A13: 12 | B13: Laura Lopez | C13: Word doc: Villa Study Scratch List (Updated Oct 2023) | D13: Oct 2023 (doc); received by email Sept 2026 | E13: Lewis Memorial Christian Village | F13: Christian Horizons | G13: Springfield, IL | H13: CCRC | I13: 20 villas | M13: CCRC (entry fee not stated) | O13: Campus amenities (bistro; chapel w/ pastor; fitness center w/ pool) | Q13: Bi-weekly housekeeping | R13: (via campus amenities) Campus amenities (bistro; chapel w/ pastor; fitness center w/ pool) | S13: Emergency response system | U13: “Paid basic cable, sewer, water and trash” | W13: “One- to two-bed, and up to two-bath townhomes”; In-unit washer/dryer; Attached garages; Private patios | Y13: Illinois Holiday Acquisitions (Springfield) | AA13: Not stated | AB13: Included | AC13: Not stated | AD13: Included | AE13: Included | AF13: Included | AG13: Not stated | AH13: Included | AI13: Not stated
A14: 13 | B14: Laura Lopez | C14: Word doc: Villa Study Scratch List (Updated Oct 2023) | D14: Oct 2023 (doc); received by email Sept 2026 | E14: Good Samaritan Home of Quincy | F14: Good Samaritan Home | G14: Quincy, IL | H14: CCRC | I14: 180 villas | M14: CCRC (entry fee not stated) | O14: Campus Amenities (gym w/ pool; chapel; buffet-style meals for add. Fee; general store) | R14: (via campus amenities) Campus Amenities (gym w/ pool; chapel; buffet-style meals for add. Fee; general store) | U14: All utilities except phone, internet, cable, and garbage stickers | W14: One and two bedroom cottages | Y14: Illinois Holiday Acquisitions (Quincy) | Z14: 1957 | AA14: Not stated | AB14: Available (extra cost) | AC14: Not stated | AD14: Not stated | AE14: Available (extra cost) | AF14: Not stated | AG14: Not stated | AH14: Included | AI14: Not stated
A15: 14 | B15: Laura Lopez | C15: Word doc: Villa Study Scratch List (Updated Oct 2023) | D15: Oct 2023 (doc); received by email Sept 2026 | E15: Provision Living at East Lansing | F15: Provision Senior Living Communities | G15: East Lansing, MI | H15: Villa, AL & MC | I15: 22 villas | M15: Not stated | Q15: Housekeeping and maintenance services | T15: Housekeeping and maintenance services | V15: Concierge services | W15: 2 Bed/2 Bath | Y15: Michigan Holiday Acquisitions (Lansing) | Z15: 2022 | AA15: Not stated | AB15: Not stated | AC15: Not stated | AD15: Included | AE15: Not stated | AF15: Not stated | AG15: Included | AH15: Not stated | AI15: Included
A16: 15 | B16: Laura Lopez | C16: Word doc: Villa Study Scratch List (Updated Oct 2023) | D16: Oct 2023 (doc); received by email Sept 2026 | E16: American House Village of Rochester Hills | F16: American House Senior Living | G16: Rochester Hills, MI | H16: rental-only continuum | I16: 12 villas (1020 – 1280 sq ft) | M16: Not stated | N16: Transportation | O16: Campus amenities (ice cream parlor; library; fitness center) | Q16: Housekeeping and laundry services | R16: (via campus amenities) Campus amenities (ice cream parlor; library; fitness center) | W16: 2-3 Bed/2 Bath; In-unit washer/dryer | Y16: Michigan Holiday Acquisitions (Waterford/Metro Detroit) | Z16: 2017 | AA16: Included | AB16: Included | AC16: Not stated | AD16: Included | AE16: Included | AF16: Not stated | AG16: Not stated | AH16: Not stated | AI16: Not stated
A17: 16 | B17: Laura Lopez | C17: Word doc: Villa Study Scratch List (Updated Oct 2023) | D17: Oct 2023 (doc); received by email Sept 2026 | E17: The Villas at Westlake | F17: Trilogy Health Services | G17: Commerce Charter Twp, MI | H17: Villa, AL, MC & SNF | I17: 34 villas | J17: 2 Bed/2 Bath: $3624 | K17: 3624 | L17: 3624 | M17: Not stated | Q17: Bi-weekly housekeeping | U17: Cable included; Electric, heat, and water included | W17: Attached garage; Private patio; Washer/dryer hookups | Y17: Michigan Holiday Acquisitions (Waterford/Metro Detroit) | Z17: 2011 | AA17: Not stated | AB17: Not stated | AC17: Not stated | AD17: Included | AE17: Not stated | AF17: Not stated | AG17: Not stated | AH17: Included | AI17: Not stated
A18: 17 | B18: Laura Lopez | C18: Word doc: Villa Study Scratch List (Updated Oct 2023) | D18: Oct 2023 (doc); received by email Sept 2026 | E18: Vitalia Senior Residences at Strongsville | F18: Arrow Senior Living | G18: Strongsville, OH | H18: Villa, AL & MC | I18: 71 Villas (1191 – 1383 sq ft) | M18: Not stated | O18: Campus amenities (wellness center; library; demonstration kitchen) | R18: (via campus amenities) Campus amenities (wellness center; library; demonstration kitchen) | W18: Attached garage; 2-3 Bed/ 2 Bath | X18: Confirm additional amenities/that it’s on par with our proposed villa product | Y18: Ohio Holiday Acquisitions (Strongsville/Cleveland) | Z18: 2024? | AA18: Not stated | AB18: Included | AC18: Not stated | AD18: Not stated | AE18: Included | AF18: Not stated | AG18: Not stated | AH18: Not stated | AI18: Not stated
A19: 18 | B19: Laura Lopez | C19: Word doc: Villa Study Scratch List (Updated Oct 2023) | D19: Oct 2023 (doc); received by email Sept 2026 | E19: Samaritas Senior Living of Grand Rapids | F19: Samaritas Senior Living | G19: Grand Rapids, MI | H19: rental-only continuum | I19: 25 Villas | J19: 1 Bedroom: $3125 | 2 Bedroom: $3645 | Stand Alone: $4045 | K19: 3125 | L19: 4045 | M19: Not stated | Y19: Michigan Holiday Acquisitions (Wyoming/Grand Rapids) | Z19: 1978 | AA19: Not stated | AB19: Not stated | AC19: Not stated | AD19: Not stated | AE19: Not stated | AF19: Not stated | AG19: Not stated | AH19: Not stated | AI19: Not stated
A20: 19 | B20: Laura Lopez | C20: Word doc: Villa Study Scratch List (Updated Oct 2023) | D20: Oct 2023 (doc); received by email Sept 2026 | E20: Legacies Village | F20: WRG Senior Living/Legacies | G20: Caledonia, MI | H20: IL | I20: 20 Villas (1200 sq ft) | M20: Not stated | P20: Daily continental breakfast in community center | U20: Utilities, including Cable & Internet | W20: 1 Bed / 1.5 Bath; In-unit washer/dryer; Attached 1-car garage; Private patio | Y20: Michigan Holiday Acquisitions (Wyoming/Grand Rapids) | Z20: 2022 | AA20: Not stated | AB20: Not stated | AC20: Included | AD20: Not stated | AE20: Not stated | AF20: Not stated | AG20: Not stated | AH20: Included | AI20: Not stated
A21: 20 | B21: Laura Lopez | C21: Word doc: Villa Study Scratch List (Updated Oct 2023) | D21: Oct 2023 (doc); received by email Sept 2026 | E21: Holiday Aurora Pond | F21: Holiday Senior Living/Atria | G21: Wyoming, MI | H21: IL | I21: 18 villas (1252 – 1474 sq ft) | J21: $4149 starting rate | K21: 4149 | L21: 4149 | M21: Not stated | O21: Campus amenities (billiards; fitness room; chapel) | R21: (via campus amenities) Campus amenities (billiards; fitness room; chapel) | U21: Cable included | W21: In-unit washer/dryer; Patio; Some w/ attached garage | Y21: Michigan Holiday Acquisitions (Wyoming/Grand Rapids) | AA21: Not stated | AB21: Included | AC21: Not stated | AD21: Not stated | AE21: Included | AF21: Not stated | AG21: Not stated | AH21: Included | AI21: Not stated
A22: 21 | B22: Laura Lopez | C22: Word doc: Villa Study Scratch List (Updated Oct 2023) | D22: Oct 2023 (doc); received by email Sept 2026 | E22: Holland Home Raybrook Campus | F22: Holland Home | G22: Grand Rapids, MI | H22: CCRC | I22: 42 Villas | M22: CCRC (entry fee not stated) | O22: Campus Amenities (billiards; wellness center; pool; library) | P22: Daily meal delivery available | R22: (via campus amenities) Campus Amenities (billiards; wellness center; pool; library) | W22: 2 Bed/2 Bath; In-unit washer/dryer; Attached garage; Patio | Y22: Michigan Holiday Acquisitions (Wyoming/Grand Rapids) | Z22: 1998 (Raybrook Homes opens); facility first established 1983 | AA22: Not stated | AB22: Included | AC22: Available (extra cost) | AD22: Not stated | AE22: Included | AF22: Not stated | AG22: Not stated | AH22: Not stated | AI22: Not stated
A23: 22 | B23: Laura Lopez | C23: Word doc: Villa Study Scratch List (Updated Oct 2023) | D23: Oct 2023 (doc); received by email Sept 2026 | E23: Breton Woods of Holland Homes | F23: Holland Home | G23: Grand Rapids, MI | H23: CCRC | I23: 126 Villas | M23: CCRC (entry fee not stated) | O23: Campus Amenities (wellness center; pool; gym; art studio; woodshop; chapel; billiards) | R23: (via campus amenities) Campus Amenities (wellness center; pool; gym; art studio; woodshop; chapel; billiards) | W23: Attached garage; In-unit washer/dryer; 2-3 Bedroom / 2-3 Bath | Y23: Michigan Holiday Acquisitions (Wyoming/Grand Rapids) | Z23: 1999 | AA23: Not stated | AB23: Included | AC23: Not stated | AD23: Not stated | AE23: Included | AF23: Not stated | AG23: Not stated | AH23: Not stated | AI23: Not stated
A24: 23 | B24: Laura Lopez | C24: Word doc: Villa Study Scratch List (Updated Oct 2023) | D24: Oct 2023 (doc); received by email Sept 2026 | E24: Waterford Place | F24: Sunset Senior Communities | G24: Jenison, MI | H24: CCRC | I24: 20 Villas (767 – 1225 sq ft) | M24: CCRC (entry fee not stated) | O24: Campus amenities (fitness/aquatics center; health clinic; library; woodshop; bistro) | R24: (via campus amenities) Campus amenities (fitness/aquatics center; health clinic; library; woodshop; bistro) | S24: Emergency response system | W24: In-unit washer/dryer; Attached two-car garage; Porch | Y24: Michigan Holiday Acquisitions (Wyoming/Grand Rapids) | Z24: 2023? | AA24: Not stated | AB24: Included | AC24: Not stated | AD24: Not stated | AE24: Included | AF24: Included | AG24: Not stated | AH24: Not stated | AI24: Not stated
A25: 24 | B25: Laura Lopez | C25: Word doc: Villa Study Scratch List (Updated Oct 2023) | D25: Oct 2023 (doc); received by email Sept 2026 | E25: Holiday Wescourt | F25: Holiday Senior Living/Atria | G25: Saginaw, MI | H25: IL | I25: 8 villas (1298 sq ft) | J25: $5219 starting rate | K25: 5219 | L25: 5219 | M25: Not stated | O25: Campus amenities (billiards; fitness room; chapel) | R25: (via campus amenities) Campus amenities (billiards; fitness room; chapel) | U25: Cable included | W25: Patio | Y25: Michigan Holiday Acquisitions (Wyoming/Grand Rapids) | AA25: Not stated | AB25: Included | AC25: Not stated | AD25: Not stated | AE25: Included | AF25: Not stated | AG25: Not stated | AH25: Included | AI25: Not stated
A26: 25 | B26: Laura Lopez | C26: Word doc: Villa Study Scratch List (Updated Oct 2023) | D26: Oct 2023 (doc); received by email Sept 2026 | E26: Vitalia North Royalton | F26: Arrow Senior Living | G26: North Royalton, OH | H26: rental-only continuum | I26: 16 villas | M26: Not stated | O26: Campus amenities (wellness center; library; demonstration kitchen) | R26: (via campus amenities) Campus amenities (wellness center; library; demonstration kitchen) | W26: Attached garage; 2-3 Bed/ 2 Bath | X26: Confirm additional amenities/that it’s on par with our proposed villa product | Y26: Ohio Holiday Acquisitions (Strongsville/Cleveland) | Z26: 2022 | AA26: Not stated | AB26: Included | AC26: Not stated | AD26: Not stated | AE26: Included | AF26: Not stated | AG26: Not stated | AH26: Not stated | AI26: Not stated
A27: 26 | B27: Laura Lopez | C27: Word doc: Villa Study Scratch List (Updated Oct 2023) | D27: Oct 2023 (doc); received by email Sept 2026 | E27: Western Reserve Masonic Community | F27: Ohio Masonic Communities | G27: Medina, OH | H27: CCRC | I27: 19 villas (1100 – 1699 sq ft) | M27: CCRC (entry fee not stated) | O27: Campus amenities (wood shop; computer lab; wellness center) | P27: 3 meals provided daily | R27: (via campus amenities) Campus amenities (wood shop; computer lab; wellness center) | U27: Water and sewer included; Wi-Fi and basic cable included | W27: 2 Bed/2 Bath | Y27: Ohio Holiday Acquisitions (Strongsville/Cleveland) | Z27: 1998 | AA27: Not stated | AB27: Included | AC27: Included | AD27: Not stated | AE27: Included | AF27: Not stated | AG27: Not stated | AH27: Included | AI27: Not stated
A28: 27 | B28: Laura Lopez | C28: Word doc: Villa Study Scratch List (Updated Oct 2023) | D28: Oct 2023 (doc); received by email Sept 2026 | E28: Provision Living at West Clermont | F28: Provision Living Senior Communities | G28: Batavia, OH | H28: Villa, AL & MC | I28: 15 villa | M28: Not stated | Q28: Housekeeping and maintenance services | T28: Housekeeping and maintenance services | V28: Concierge | W28: 2 Bed/2 Bath | Y28: Ohio Holiday Acquisitions (Cincinnati) | Z28: 2021 | AA28: Not stated | AB28: Not stated | AC28: Not stated | AD28: Included | AE28: Not stated | AF28: Not stated | AG28: Included | AH28: Not stated | AI28: Included
A29: 28 | B29: Laura Lopez | C29: Word doc: Villa Study Scratch List (Updated Oct 2023) | D29: Oct 2023 (doc); received by email Sept 2026 | E29: Solarbron | F29: CarDon & Associates | G29: Evansville, IN | H29: rental-only continuum | I29: 9 villa | M29: Not stated | O29: Campus amenities (shuffleboard courts; billiards/games room; fitness center; business center; private fishing lake; vegetable/flower gardens) | R29: (via campus amenities) Campus amenities (shuffleboard courts; billiards/games room; fitness center; business center; private fishing lake; vegetable/flower gardens) | S29: Emergency alert system | U29: Basic cable, water, sewer, and trash removal | W29: 2-3 Bed/2 Bath; Attached double garage; Laundry room with washer/dryer hookups | Y29: Indiana Holiday Acquisitions (Evansville) | AA29: Not stated | AB29: Included | AC29: Not stated | AD29: Not stated | AE29: Included | AF29: Included | AG29: Not stated | AH29: Included | AI29: Not stated
A30: 29 | B30: Laura Lopez | C30: Word doc: Villa Study Scratch List (Updated Oct 2023) | D30: Oct 2023 (doc); received by email Sept 2026 | E30: The Village at Hamilton Pointe | F30: TLC Management | G30: Newburgh, IN | H30: rental-only continuum | I30: 24 villas | M30: Not stated | N30: Transportation | O30: Gardens; Campus amenities (movie theater; salon/spa; therapy gym) | P30: “Deliciously prepared chef inspired meals” (doesn’t specify which or how many daily) | R30: (via campus amenities) Campus amenities (movie theater; salon/spa; therapy gym) | U30: Paid utilities | W30: One- and two-bedroom cottages – 1 bath; Washers/dryers (two-bedroom layouts only); Porches | Y30: Indiana Holiday Acquisitions (Evansville) | Z30: 2013 | AA30: Included | AB30: Included | AC30: Included | AD30: Not stated | AE30: Included | AF30: Not stated | AG30: Not stated | AH30: Included | AI30: Not stated
A31: 30 | B31: Laura Lopez | C31: Word doc: Villa Study Scratch List (Updated Oct 2023) | D31: Oct 2023 (doc); received by email Sept 2026 | E31: Athens Crossing at Four Seasons | F31: BHI Senior Living | G31: Columbus, IN | H31: CCRC | I31: 12 villas (1850 – 2400 sq ft) | M31: CCRC (entry fee not stated) | O31: Campus amenities (indoor pool; fitness center; dog park; rehab center) | R31: (via campus amenities) Campus amenities (indoor pool; fitness center; dog park; rehab center) | U31: Utilities included (excluding cable, phone, and internet) | W31: 2 Bed/2 Bath; In-unit washer/dryer; Fireplace; Patio or covered porch; Island kitchen counter; Attached two-car garage | Y31: Indiana Holiday Acquisitions (Columbus/Indianapolis) | Z31: 2023? | AA31: Not stated | AB31: Included | AC31: Not stated | AD31: Not stated | AE31: Included | AF31: Not stated | AG31: Not stated | AH31: Included | AI31: Not stated
A32: 31 | B32: Laura Lopez | C32: Word doc: Villa Study Scratch List (Updated Oct 2023) | D32: Oct 2023 (doc); received by email Sept 2026 | E32: Traditions of Columbus | F32: Traditions Management | G32: Columbus, IN | H32: rental-only continuum | I32: 30 villas (1481 – 1530 sq ft) | M32: Not stated | O32: Campus amenities (pub; chapel; movie theater; fitness center; salon) | R32: (via campus amenities) Campus amenities (pub; chapel; movie theater; fitness center; salon) | S32: Gated security; Emergency response system | U32: All utilities, including cable & internet | W32: 2 Bed/2 Bath; Attached single-car garage; In-unit washer/dryer; Covered porch/patio | Y32: Indiana Holiday Acquisitions (Columbus/Indianapolis) | Z32: 2021 | AA32: Not stated | AB32: Included | AC32: Not stated | AD32: Not stated | AE32: Included | AF32: Included | AG32: Not stated | AH32: Included | AI32: Not stated
A33: 32 | B33: Laura Lopez | C33: Word doc: Villa Study Scratch List (Updated Oct 2023) | D33: Oct 2023 (doc); received by email Sept 2026 | E33: The Heritage at Brentwood | F33: Life Care Services LLC | G33: Brentwood, TN | H33: CCRC | I33: 65 villas (1803 – 2171 sq ft) | M33: CCRC (entry fee not stated) | N33: Transportation | O33: Campus amenities (multiple dining venues; putting green; bocce court; woodworking shop; art studio; greenhouse/gardening area; market; medical clinic; bank services) | R33: (via campus amenities) Campus amenities (multiple dining venues; putting green; bocce court; woodworking shop; art studio; greenhouse/gardening area; market; medical clinic; bank services) | U33: Cable TV and Wi-Fi | W33: 2-3 Bed/2-3 Bath; Attached garage; In-unit washer/dryer | Y33: Tennessee Holiday Acquisitions (Franklin) | Z33: 2009 | AA33: Included | AB33: Included | AC33: Not stated | AD33: Not stated | AE33: Included | AF33: Not stated | AG33: Not stated | AH33: Included | AI33: Not stated
A34: 33 | B34: Laura Lopez | C34: Word doc: Villa Study Scratch List (Updated Oct 2023) | D34: Oct 2023 (doc); received by email Sept 2026 | E34: Holiday Mallard Point | F34: Holiday/Atria | G34: Cedar Falls, IA | H34: IL | I34: 8 villas (743 sq ft) | J34: $3239 | K34: 3239 | L34: 3239 | M34: Not stated | O34: Campus amenities (billiards; fitness room; salon) | R34: (via campus amenities) Campus amenities (billiards; fitness room; salon) | Y34: Iowa Holiday Acquisitions (Cedar Falls) | AA34: Not stated | AB34: Included | AC34: Not stated | AD34: Not stated | AE34: Included | AF34: Not stated | AG34: Not stated | AH34: Not stated | AI34: Not stated
A35: 34 | B35: Laura Lopez | C35: Word doc: Villa Study Scratch List (Updated Oct 2023) | D35: Oct 2023 (doc); received by email Sept 2026 | E35: Windcrest | F35: Western Home Communities | G35: Cedar Falls, IA | H35: CCRC | I35: 174 villas (1150 – 1450 sq ft) | M35: CCRC (entry fee not stated) | O35: Campus amenities (pub; salon; wellness/aquatic center; chapel; therapy; market; fine dining) | R35: (via campus amenities) Campus amenities (pub; salon; wellness/aquatic center; chapel; therapy; market; fine dining) | T35: Lawn Care and Mowing; Snow Removal; Service requests | Y35: Iowa Holiday Acquisitions (Cedar Falls) | Z35: 2000 | AA35: Not stated | AB35: Included | AC35: Not stated | AD35: Not stated | AE35: Included | AF35: Not stated | AG35: Included | AH35: Not stated | AI35: Not stated
A36: 35 | B36: Laura Lopez | C36: Word doc: Villa Study Scratch List (Updated Oct 2023) | D36: Oct 2023 (doc); received by email Sept 2026 | E36: Friendship Village | F36: Friendship Village | G36: Waterloo, IA | H36: CCRC | I36: 8 villas | M36: CCRC (entry fee not stated) | O36: Campus amenities (chapel w/ chaplain; billiards; woodshop; media center; library; bistro) | P36: Included meals | Q36: Housekeeping services | W36: Attached two-car garage | Y36: Iowa Holiday Acquisitions (Cedar Falls) | AA36: Not stated | AB36: Included | AC36: Included | AD36: Included | AE36: Not stated | AF36: Not stated | AG36: Not stated | AH36: Not stated | AI36: Not stated
A37: 36 | B37: Laura Lopez | C37: Word doc: Villa Study Scratch List (Updated Oct 2023) | D37: Oct 2023 (doc); received by email Sept 2026 | E37: Landmark Commons | F37: Friendship Village | G37: Waterloo, IA | H37: IL | I37: 15 villas | M37: Not stated | O37: Campus amenities (bistro; craft room; woodshop; billiards; wellness center w/ pool) | P37: Continental breakfast | Q37: Weekly housekeeping | R37: (via campus amenities) Campus amenities (bistro; craft room; woodshop; billiards; wellness center w/ pool) | U37: Utilities, including Cable, Internet & Phone | W37: Attached two-car garage | Y37: Iowa Holiday Acquisitions (Cedar Falls) | AA37: Not stated | AB37: Included | AC37: Included | AD37: Included | AE37: Included | AF37: Not stated | AG37: Not stated | AH37: Included | AI37: Not stated
A38: 37 | B38: Laura Lopez | C38: Word doc: Villa Study Scratch List (Updated Oct 2023) | D38: Oct 2023 (doc); received by email Sept 2026 | E38: NewAldaya Lifescapes | F38: NewAldaya | G38: Cedar Falls, IA | H38: CCRC | I38: 14 villas (Park Ridge Ranches; 650 – 1300 sq ft) | M38: CCRC (entry fee not stated) | O38: Campus amenities (general store; spa; pub; wellness center; chapel; café) | R38: (via campus amenities) Campus amenities (general store; spa; pub; wellness center; chapel; café) | W38: In-unit washer/dryer; Some w/ attached garages; Private patio | Y38: Iowa Holiday Acquisitions (Cedar Falls) | AA38: Not stated | AB38: Included | AC38: Not stated | AD38: Not stated | AE38: Included | AF38: Not stated | AG38: Not stated | AH38: Not stated | AI38: Not stated
A39: 38 | B39: Laura Lopez | C39: Word doc: Villa Study Scratch List (Updated Oct 2023) | D39: Oct 2023 (doc); received by email Sept 2026 | E39: Brio of Johnston | F39: Wesley Life, Inc. | G39: Johnston, IA | H39: CCRC | I39: 19 villas | M39: CCRC (entry fee not stated) | O39: Campus amenities:; Library; Salon; Chapel; General Store; Onsite banking; Bistro | R39: Wellness/fitness center | Y39: Iowa Holiday Acquisitions (Des Moines) | Z39: 2018 | AA39: Not stated | AB39: Included | AC39: Not stated | AD39: Not stated | AE39: Included | AF39: Not stated | AG39: Not stated | AH39: Not stated | AI39: Not stated
A40: 39 | B40: Laura Lopez | C40: Word doc: Villa Study Scratch List (Updated Oct 2023) | D40: Oct 2023 (doc); received by email Sept 2026 | E40: Deerfield Retirement Community | F40: Immanuel Communities | G40: Urbandale, IA | H40: CCRC | I40: 18 villas (1920+ sq ft) | M40: CCRC (entry fee not stated) | N40: Transportation | O40: Campus amenities (bistro; convenience store; woodworking shop; game room; fishing dock/pond; cocktail lounge; access to walking/biking trails) | U40: Paid utilities, including cable | W40: Attached two-car garage; Private patio | Y40: Iowa Holiday Acquisitions (Des Moines) | Z40: 2005 | AA40: Included | AB40: Included | AC40: Not stated | AD40: Not stated | AE40: Not stated | AF40: Not stated | AG40: Not stated | AH40: Included | AI40: Not stated
...

Sheet Synthesis
A1: Synthesis — Cottage / Villa Service Offerings Across Four Sources
A2: All counts below are live formulas over the Consolidated Data tab (tier columns). Narrative cells summarize what each source reported.
A4: 1. Service coverage by function — how often each function is reported
A5: Function | B5: Source | C5: n (rows) | D5: Included | E5: Included (limited) | F5: Available (extra cost) | G5: Not provided | H5: Not stated | I5: Any mention | J5: % any mention | K5: % included (of mentions)
A6: Transportation | B6: Laura Lopez | C6: =COUNTIF('Consolidated Data'!$B$2:$B$231,"Laura Lopez") -> 215 | D6: =COUNTIFS('Consolidated Data'!$B$2:$B$231,"Laura Lopez",'Consolidated Data'!$AA$2:$AA$231,"Included") -> 55 | E6: =COUNTIFS('Consolidated Data'!$B$2:$B$231,"Laura Lopez",'Consolidated Data'!$AA$2:$AA$231,"Included (limited)") -> 0 | F6: =COUNTIFS('Consolidated Data'!$B$2:$B$231,"Laura Lopez",'Consolidated Data'!$AA$2:$AA$231,"Available (extra cost)") -> 0 | G6: =COUNTIFS('Consolidated Data'!$B$2:$B$231,"Laura Lopez",'Consolidated Data'!$AA$2:$AA$231,"Not provided") -> 0 | H6: =COUNTIFS('Consolidated Data'!$B$2:$B$231,"Laura Lopez",'Consolidated Data'!$AA$2:$AA$231,"Not stated") -> 160 | I6: =C6-H6 -> 55 | J6: =IF(C6=0,0,I6/C6) -> 0.25581395 | K6: =IF(I6=0,0,(D6+E6)/I6) -> 1
A7: Transportation | B7: Jennifer Saxman | C7: =COUNTIF('Consolidated Data'!$B$2:$B$231,"Jennifer Saxman") -> 11 | D7: =COUNTIFS('Consolidated Data'!$B$2:$B$231,"Jennifer Saxman",'Consolidated Data'!$AA$2:$AA$231,"Included") -> 7 | E7: =COUNTIFS('Consolidated Data'!$B$2:$B$231,"Jennifer Saxman",'Consolidated Data'!$AA$2:$AA$231,"Included (limited)") -> 0 | F7: =COUNTIFS('Consolidated Data'!$B$2:$B$231,"Jennifer Saxman",'Consolidated Data'!$AA$2:$AA$231,"Available (extra cost)") -> 3 | G7: =COUNTIFS('Consolidated Data'!$B$2:$B$231,"Jennifer Saxman",'Consolidated Data'!$AA$2:$AA$231,"Not provided") -> 1 | H7: =COUNTIFS('Consolidated Data'!$B$2:$B$231,"Jennifer Saxman",'Consolidated Data'!$AA$2:$AA$231,"Not stated") -> 0 | I7: =C7-H7 -> 11 | J7: =IF(C7=0,0,I7/C7) -> 1 | K7: =IF(I7=0,0,(D7+E7)/I7) -> 0.63636364
A8: Life Enrichment / Campus Amenities | B8: Laura Lopez | C8: =COUNTIF('Consolidated Data'!$B$2:$B$231,"Laura Lopez") -> 215 | D8: =COUNTIFS('Consolidated Data'!$B$2:$B$231,"Laura Lopez",'Consolidated Data'!$AB$2:$AB$231,"Included") -> 52 | E8: =COUNTIFS('Consolidated Data'!$B$2:$B$231,"Laura Lopez",'Consolidated Data'!$AB$2:$AB$231,"Included (limited)") -> 0 | F8: =COUNTIFS('Consolidated Data'!$B$2:$B$231,"Laura Lopez",'Consolidated Data'!$AB$2:$AB$231,"Available (extra cost)") -> 2 | G8: =COUNTIFS('Consolidated Data'!$B$2:$B$231,"Laura Lopez",'Consolidated Data'!$AB$2:$AB$231,"Not provided") -> 0 | H8: =COUNTIFS('Consolidated Data'!$B$2:$B$231,"Laura Lopez",'Consolidated Data'!$AB$2:$AB$231,"Not stated") -> 161 | I8: =C8-H8 -> 54 | J8: =IF(C8=0,0,I8/C8) -> 0.25116279 | K8: =IF(I8=0,0,(D8+E8)/I8) -> 0.96296296
A9: Life Enrichment / Campus Amenities | B9: Jennifer Saxman | C9: =COUNTIF('Consolidated Data'!$B$2:$B$231,"Jennifer Saxman") -> 11 | D9: =COUNTIFS('Consolidated Data'!$B$2:$B$231,"Jennifer Saxman",'Consolidated Data'!$AB$2:$AB$231,"Included") -> 7 | E9: =COUNTIFS('Consolidated Data'!$B$2:$B$231,"Jennifer Saxman",'Consolidated Data'!$AB$2:$AB$231,"Included (limited)") -> 1 | F9: =COUNTIFS('Consolidated Data'!$B$2:$B$231,"Jennifer Saxman",'Consolidated Data'!$AB$2:$AB$231,"Available (extra cost)") -> 3 | G9: =COUNTIFS('Consolidated Data'!$B$2:$B$231,"Jennifer Saxman",'Consolidated Data'!$AB$2:$AB$231,"Not provided") -> 0 | H9: =COUNTIFS('Consolidated Data'!$B$2:$B$231,"Jennifer Saxman",'Consolidated Data'!$AB$2:$AB$231,"Not stated") -> 0 | I9: =C9-H9 -> 11 | J9: =IF(C9=0,0,I9/C9) -> 1 | K9: =IF(I9=0,0,(D9+E9)/I9) -> 0.72727273
A10: Culinary / Dining | B10: Laura Lopez | C10: =COUNTIF('Consolidated Data'!$B$2:$B$231,"Laura Lopez") -> 215 | D10: =COUNTIFS('Consolidated Data'!$B$2:$B$231,"Laura Lopez",'Consolidated Data'!$AC$2:$AC$231,"Included") -> 36 | E10: =COUNTIFS('Consolidated Data'!$B$2:$B$231,"Laura Lopez",'Consolidated Data'!$AC$2:$AC$231,"Included (limited)") -> 0 | F10: =COUNTIFS('Consolidated Data'!$B$2:$B$231,"Laura Lopez",'Consolidated Data'!$AC$2:$AC$231,"Available (extra cost)") -> 17 | G10: =COUNTIFS('Consolidated Data'!$B$2:$B$231,"Laura Lopez",'Consolidated Data'!$AC$2:$AC$231,"Not provided") -> 0 | H10: =COUNTIFS('Consolidated Data'!$B$2:$B$231,"Laura Lopez",'Consolidated Data'!$AC$2:$AC$231,"Not stated") -> 162 | I10: =C10-H10 -> 53 | J10: =IF(C10=0,0,I10/C10) -> 0.24651163 | K10: =IF(I10=0,0,(D10+E10)/I10) -> 0.67924528
A11: Culinary / Dining | B11: Jennifer Saxman | C11: =COUNTIF('Consolidated Data'!$B$2:$B$231,"Jennifer Saxman") -> 11 | D11: =COUNTIFS('Consolidated Data'!$B$2:$B$231,"Jennifer Saxman",'Consolidated Data'!$AC$2:$AC$231,"Included") -> 3 | E11: =COUNTIFS('Consolidated Data'!$B$2:$B$231,"Jennifer Saxman",'Consolidated Data'!$AC$2:$AC$231,"Included (limited)") -> 0 | F11: =COUNTIFS('Consolidated Data'!$B$2:$B$231,"Jennifer Saxman",'Consolidated Data'!$AC$2:$AC$231,"Available (extra cost)") -> 7 | G11: =COUNTIFS('Consolidated Data'!$B$2:$B$231,"Jennifer Saxman",'Consolidated Data'!$AC$2:$AC$231,"Not provided") -> 1 | H11: =COUNTIFS('Consolidated Data'!$B$2:$B$231,"Jennifer Saxman",'Consolidated Data'!$AC$2:$AC$231,"Not stated") -> 0 | I11: =C11-H11 -> 11 | J11: =IF(C11=0,0,I11/C11) -> 1 | K11: =IF(I11=0,0,(D11+E11)/I11) -> 0.27272727
A12: Housekeeping / Laundry & Linen | B12: Laura Lopez | C12: =COUNTIF('Consolidated Data'!$B$2:$B$231,"Laura Lopez") -> 215 | D12: =COUNTIFS('Consolidated Data'!$B$2:$B$231,"Laura Lopez",'Consolidated Data'!$AD$2:$AD$231,"Included") -> 60 | E12: =COUNTIFS('Consolidated Data'!$B$2:$B$231,"Laura Lopez",'Consolidated Data'!$AD$2:$AD$231,"Included (limited)") -> 0 | F12: =COUNTIFS('Consolidated Data'!$B$2:$B$231,"Laura Lopez",'Consolidated Data'!$AD$2:$AD$231,"Available (extra cost)") -> 9 | G12: =COUNTIFS('Consolidated Data'!$B$2:$B$231,"Laura Lopez",'Consolidated Data'!$AD$2:$AD$231,"Not provided") -> 0 | H12: =COUNTIFS('Consolidated Data'!$B$2:$B$231,"Laura Lopez",'Consolidated Data'!$AD$2:$AD$231,"Not stated") -> 146 | I12: =C12-H12 -> 69 | J12: =IF(C12=0,0,I12/C12) -> 0.32093023 | K12: =IF(I12=0,0,(D12+E12)/I12) -> 0.86956522
A13: Housekeeping / Laundry & Linen | B13: Jennifer Saxman | C13: =COUNTIF('Consolidated Data'!$B$2:$B$231,"Jennifer Saxman") -> 11 | D13: =COUNTIFS('Consolidated Data'!$B$2:$B$231,"Jennifer Saxman",'Consolidated Data'!$AD$2:$AD$231,"Included") -> 6 | E13: =COUNTIFS('Consolidated Data'!$B$2:$B$231,"Jennifer Saxman",'Consolidated Data'!$AD$2:$AD$231,"Included (limited)") -> 0 | F13: =COUNTIFS('Consolidated Data'!$B$2:$B$231,"Jennifer Saxman",'Consolidated Data'!$AD$2:$AD$231,"Available (extra cost)") -> 5 | G13: =COUNTIFS('Consolidated Data'!$B$2:$B$231,"Jennifer Saxman",'Consolidated Data'!$AD$2:$AD$231,"Not provided") -> 0 | H13: =COUNTIFS('Consolidated Data'!$B$2:$B$231,"Jennifer Saxman",'Consolidated Data'!$AD$2:$AD$231,"Not stated") -> 0 | I13: =C13-H13 -> 11 | J13: =IF(C13=0,0,I13/C13) -> 1 | K13: =IF(I13=0,0,(D13+E13)/I13) -> 0.54545455
A14: Wellness / Fitness / Health | B14: Laura Lopez | C14: =COUNTIF('Consolidated Data'!$B$2:$B$231,"Laura Lopez") -> 215 | D14: =COUNTIFS('Consolidated Data'!$B$2:$B$231,"Laura Lopez",'Consolidated Data'!$AE$2:$AE$231,"Included") -> 48 | E14: =COUNTIFS('Consolidated Data'!$B$2:$B$231,"Laura Lopez",'Consolidated Data'!$AE$2:$AE$231,"Included (limited)") -> 0 | F14: =COUNTIFS('Consolidated Data'!$B$2:$B$231,"Laura Lopez",'Consolidated Data'!$AE$2:$AE$231,"Available (extra cost)") -> 12 | G14: =COUNTIFS('Consolidated Data'!$B$2:$B$231,"Laura Lopez",'Consolidated Data'!$AE$2:$AE$231,"Not provided") -> 0 | H14: =COUNTIFS('Consolidated Data'!$B$2:$B$231,"Laura Lopez",'Consolidated Data'!$AE$2:$AE$231,"Not stated") -> 155 | I14: =C14-H14 -> 60 | J14: =IF(C14=0,0,I14/C14) -> 0.27906977 | K14: =IF(I14=0,0,(D14+E14)/I14) -> 0.8
A15: Wellness / Fitness / Health | B15: Jennifer Saxman | C15: =COUNTIF('Consolidated Data'!$B$2:$B$231,"Jennifer Saxman") -> 11 | D15: =COUNTIFS('Consolidated Data'!$B$2:$B$231,"Jennifer Saxman",'Consolidated Data'!$AE$2:$AE$231,"Included") -> 7 | E15: =COUNTIFS('Consolidated Data'!$B$2:$B$231,"Jennifer Saxman",'Consolidated Data'!$AE$2:$AE$231,"Included (limited)") -> 1 | F15: =COUNTIFS('Consolidated Data'!$B$2:$B$231,"Jennifer Saxman",'Consolidated Data'!$AE$2:$AE$231,"Available (extra cost)") -> 3 | G15: =COUNTIFS('Consolidated Data'!$B$2:$B$231,"Jennifer Saxman",'Consolidated Data'!$AE$2:$AE$231,"Not provided") -> 0 | H15: =COUNTIFS('Consolidated Data'!$B$2:$B$231,"Jennifer Saxman",'Consolidated Data'!$AE$2:$AE$231,"Not stated") -> 0 | I15: =C15-H15 -> 11 | J15: =IF(C15=0,0,I15/C15) -> 1 | K15: =IF(I15=0,0,(D15+E15)/I15) -> 0.72727273
A16: Emergency / Safety / Security | B16: Laura Lopez | C16: =COUNTIF('Consolidated Data'!$B$2:$B$231,"Laura Lopez") -> 215 | D16: =COUNTIFS('Consolidated Data'!$B$2:$B$231,"Laura Lopez",'Consolidated Data'!$AF$2:$AF$231,"Included") -> 74 | E16: =COUNTIFS('Consolidated Data'!$B$2:$B$231,"Laura Lopez",'Consolidated Data'!$AF$2:$AF$231,"Included (limited)") -> 0 | F16: =COUNTIFS('Consolidated Data'!$B$2:$B$231,"Laura Lopez",'Consolidated Data'!$AF$2:$AF$231,"Available (extra cost)") -> 2 | G16: =COUNTIFS('Consolidated Data'!$B$2:$B$231,"Laura Lopez",'Consolidated Data'!$AF$2:$AF$231,"Not provided") -> 0 | H16: =COUNTIFS('Consolidated Data'!$B$2:$B$231,"Laura Lopez",'Consolidated Data'!$AF$2:$AF$231,"Not stated") -> 139 | I16: =C16-H16 -> 76 | J16: =IF(C16=0,0,I16/C16) -> 0.35348837 | K16: =IF(I16=0,0,(D16+E16)/I16) -> 0.97368421
A17: Emergency / Safety / Security | B17: Jennifer Saxman | C17: =COUNTIF('Consolidated Data'!$B$2:$B$231,"Jennifer Saxman") -> 11 | D17: =COUNTIFS('Consolidated Data'!$B$2:$B$231,"Jennifer Saxman",'Consolidated Data'!$AF$2:$AF$231,"Included") -> 9 | E17: =COUNTIFS('Consolidated Data'!$B$2:$B$231,"Jennifer Saxman",'Consolidated Data'!$AF$2:$AF$231,"Included (limited)") -> 0 | F17: =COUNTIFS('Consolidated Data'!$B$2:$B$231,"Jennifer Saxman",'Consolidated Data'!$AF$2:$AF$231,"Available (extra cost)") -> 2 | G17: =COUNTIFS('Consolidated Data'!$B$2:$B$231,"Jennifer Saxman",'Consolidated Data'!$AF$2:$AF$231,"Not provided") -> 0 | H17: =COUNTIFS('Consolidated Data'!$B$2:$B$231,"Jennifer Saxman",'Consolidated Data'!$AF$2:$AF$231,"Not stated") -> 0 | I17: =C17-H17 -> 11 | J17: =IF(C17=0,0,I17/C17) -> 1 | K17: =IF(I17=0,0,(D17+E17)/I17) -> 0.81818182
A18: Maintenance (Interior / Exterior / Grounds) | B18: Laura Lopez | C18: =COUNTIF('Consolidated Data'!$B$2:$B$231,"Laura Lopez") -> 215 | D18: =COUNTIFS('Consolidated Data'!$B$2:$B$231,"Laura Lopez",'Consolidated Data'!$AG$2:$AG$231,"Included") -> 102 | E18: =COUNTIFS('Consolidated Data'!$B$2:$B$231,"Laura Lopez",'Consolidated Data'!$AG$2:$AG$231,"Included (limited)") -> 0 | F18: =COUNTIFS('Consolidated Data'!$B$2:$B$231,"Laura Lopez",'Consolidated Data'!$AG$2:$AG$231,"Available (extra cost)") -> 1 | G18: =COUNTIFS('Consolidated Data'!$B$2:$B$231,"Laura Lopez",'Consolidated Data'!$AG$2:$AG$231,"Not provided") -> 0 | H18: =COUNTIFS('Consolidated Data'!$B$2:$B$231,"Laura Lopez",'Consolidated Data'!$AG$2:$AG$231,"Not stated") -> 112 | I18: =C18-H18 -> 103 | J18: =IF(C18=0,0,I18/C18) -> 0.47906977 | K18: =IF(I18=0,0,(D18+E18)/I18) -> 0.99029126
A19: Maintenance (Interior / Exterior / Grounds) | B19: Jennifer Saxman | C19: =COUNTIF('Consolidated Data'!$B$2:$B$231,"Jennifer Saxman") -> 11 | D19: =COUNTIFS('Consolidated Data'!$B$2:$B$231,"Jennifer Saxman",'Consolidated Data'!$AG$2:$AG$231,"Included") -> 11 | E19: =COUNTIFS('Consolidated Data'!$B$2:$B$231,"Jennifer Saxman",'Consolidated Data'!$AG$2:$AG$231,"Included (limited)") -> 0 | F19: =COUNTIFS('Consolidated Data'!$B$2:$B$231,"Jennifer Saxman",'Consolidated Data'!$AG$2:$AG$231,"Available (extra cost)") -> 0 | G19: =COUNTIFS('Consolidated Data'!$B$2:$B$231,"Jennifer Saxman",'Consolidated Data'!$AG$2:$AG$231,"Not provided") -> 0 | H19: =COUNTIFS('Consolidated Data'!$B$2:$B$231,"Jennifer Saxman",'Consolidated Data'!$AG$2:$AG$231,"Not stated") -> 0 | I19: =C19-H19 -> 11 | J19: =IF(C19=0,0,I19/C19) -> 1 | K19: =IF(I19=0,0,(D19+E19)/I19) -> 1
A20: Utilities / Taxes / Insurance | B20: Laura Lopez | C20: =COUNTIF('Consolidated Data'!$B$2:$B$231,"Laura Lopez") -> 215 | D20: =COUNTIFS('Consolidated Data'!$B$2:$B$231,"Laura Lopez",'Consolidated Data'!$AH$2:$AH$231,"Included") -> 118 | E20: =COUNTIFS('Consolidated Data'!$B$2:$B$231,"Laura Lopez",'Consolidated Data'!$AH$2:$AH$231,"Included (limited)") -> 0 | F20: =COUNTIFS('Consolidated Data'!$B$2:$B$231,"Laura Lopez",'Consolidated Data'!$AH$2:$AH$231,"Available (extra cost)") -> 2 | G20: =COUNTIFS('Consolidated Data'!$B$2:$B$231,"Laura Lopez",'Consolidated Data'!$AH$2:$AH$231,"Not provided") -> 0 | H20: =COUNTIFS('Consolidated Data'!$B$2:$B$231,"Laura Lopez",'Consolidated Data'!$AH$2:$AH$231,"Not stated") -> 95 | I20: =C20-H20 -> 120 | J20: =IF(C20=0,0,I20/C20) -> 0.55813953 | K20: =IF(I20=0,0,(D20+E20)/I20) -> 0.98333333
A21: Utilities / Taxes / Insurance | B21: Jennifer Saxman | C21: =COUNTIF('Consolidated Data'!$B$2:$B$231,"Jennifer Saxman") -> 11 | D21: =COUNTIFS('Consolidated Data'!$B$2:$B$231,"Jennifer Saxman",'Consolidated Data'!$AH$2:$AH$231,"Included") -> 11 | E21: =COUNTIFS('Consolidated Data'!$B$2:$B$231,"Jennifer Saxman",'Consolidated Data'!$AH$2:$AH$231,"Included (limited)") -> 0 | F21: =COUNTIFS('Consolidated Data'!$B$2:$B$231,"Jennifer Saxman",'Consolidated Data'!$AH$2:$AH$231,"Available (extra cost)") -> 0 | G21: =COUNTIFS('Consolidated Data'!$B$2:$B$231,"Jennifer Saxman",'Consolidated Data'!$AH$2:$AH$231,"Not provided") -> 0 | H21: =COUNTIFS('Consolidated Data'!$B$2:$B$231,"Jennifer Saxman",'Consolidated Data'!$AH$2:$AH$231,"Not stated") -> 0 | I21: =C21-H21 -> 11 | J21: =IF(C21=0,0,I21/C21) -> 1 | K21: =IF(I21=0,0,(D21+E21)/I21) -> 1
A22: Additional / À La Carte / Concierge | B22: Laura Lopez | C22: =COUNTIF('Consolidated Data'!$B$2:$B$231,"Laura Lopez") -> 215 | D22: =COUNTIFS('Consolidated Data'!$B$2:$B$231,"Laura Lopez",'Consolidated Data'!$AI$2:$AI$231,"Included") -> 10 | E22: =COUNTIFS('Consolidated Data'!$B$2:$B$231,"Laura Lopez",'Consolidated Data'!$AI$2:$AI$231,"Included (limited)") -> 0 | F22: =COUNTIFS('Consolidated Data'!$B$2:$B$231,"Laura Lopez",'Consolidated Data'!$AI$2:$AI$231,"Available (extra cost)") -> 4 | G22: =COUNTIFS('Consolidated Data'!$B$2:$B$231,"Laura Lopez",'Consolidated Data'!$AI$2:$AI$231,"Not provided") -> 0 | H22: =COUNTIFS('Consolidated Data'!$B$2:$B$231,"Laura Lopez",'Consolidated Data'!$AI$2:$AI$231,"Not stated") -> 201 | I22: =C22-H22 -> 14 | J22: =IF(C22=0,0,I22/C22) -> 0.065116279 | K22: =IF(I22=0,0,(D22+E22)/I22) -> 0.71428571
A23: Additional / À La Carte / Concierge | B23: Jennifer Saxman | C23: =COUNTIF('Consolidated Data'!$B$2:$B$231,"Jennifer Saxman") -> 11 | D23: =COUNTIFS('Consolidated Data'!$B$2:$B$231,"Jennifer Saxman",'Consolidated Data'!$AI$2:$AI$231,"Included") -> 5 | E23: =COUNTIFS('Consolidated Data'!$B$2:$B$231,"Jennifer Saxman",'Consolidated Data'!$AI$2:$AI$231,"Included (limited)") -> 1 | F23: =COUNTIFS('Consolidated Data'!$B$2:$B$231,"Jennifer Saxman",'Consolidated Data'!$AI$2:$AI$231,"Available (extra cost)") -> 5 | G23: =COUNTIFS('Consolidated Data'!$B$2:$B$231,"Jennifer Saxman",'Consolidated Data'!$AI$2:$AI$231,"Not provided") -> 0 | H23: =COUNTIFS('Consolidated Data'!$B$2:$B$231,"Jennifer Saxman",'Consolidated Data'!$AI$2:$AI$231,"Not stated") -> 0 | I23: =C23-H23 -> 11 | J23: =IF(C23=0,0,I23/C23) -> 1 | K23: =IF(I23=0,0,(D23+E23)/I23) -> 0.54545455
A24: Reading note: Lopez rows are a web-researched inventory (Oct 2023) where "Not stated" usually means the community website did not list that service, not that it is absent. Saxman rows include the 6-community table plus narrative examples. Witzgall (2 model rows) and Wood (2 rows) are excluded from counts because they are not community-level inventories.
A26: 2. Pricing snapshot
A27: Metric | B27: Value | C27: Source / basis
A28: Lopez: communities with a monthly fee reported | B28: =COUNTIFS('Consolidated Data'!$B$2:$B$231,"Laura Lopez",'Consolidated Data'!$K$2:$K$231,">0") -> 54 | C28: Consolidated Data col K (parsed from reported pricing)
A29: Lopez: lowest reported monthly fee | B29: =MIN('Consolidated Data'!$K$2:$K$216) -> 515 | C29: see note
A30: Lopez: median reported monthly fee (low end of each range) | B30: =MEDIAN('Consolidated Data'!$K$2:$K$216) -> 2799.5 | C30: Consolidated Data col K, Lopez rows only
A31: Lopez: highest reported monthly fee | B31: =MAX('Consolidated Data'!$L$2:$L$216) -> 6900 | C31: Consolidated Data col L, Lopez rows only
A32: Lopez: communities confirmed to require an entry / entrance fee | B32: =COUNTIFS('Consolidated Data'!$B$2:$B$231,"Laura Lopez",'Consolidated Data'!$M$2:$M$231,"Yes") -> 63 | C32: Consolidated Data col M
A33: Lopez: additional CCRCs where entry fee not stated | B33: =COUNTIFS('Consolidated Data'!$B$2:$B$231,"Laura Lopez",'Consolidated Data'!$M$2:$M$231,"CCRC (entry fee not stated)") -> 35 | C33: Consolidated Data col M
A34: Witzgall: typical rental cottage monthly fee | B34: $2,500 – $6,500+ per month | C34: Witzgall PDF, fee table (rental model; 900 – 1,800+ sq ft)
A35: Witzgall: one-time move-in / community fee | B35: $1,000 – $5,000 (non-refundable) | C35: Witzgall PDF
A36: Witzgall: second-person fee | B36: $500 – $1,000 per month | C36: Witzgall PDF
A37: Witzgall: rental cottage premium vs. IL apartment | B37: 15% – 30% monthly premium over IL apartments of similar size ($2,200 – $4,500/mo) | C37: Witzgall PDF, strategic takeaways
A38: Witzgall: dining upgrade to 3 meals/day | B38: $600 – $900 per month | C38: Witzgall PDF
A39: Witzgall: weekly housekeeping upgrade | B39: +$150 – $300 per month over bi-weekly base | C39: Witzgall PDF
A40: Saxman: optional housekeeping (Highgrove at Tates Creek) | B40: approx. $240 per month | C40: Saxman email
A41: Lopez: à la carte housekeeping (Legacy Living Florence) | B41: $25 per hour | C41: Lopez inventory
A42: Note: Lopez min/median/max ranges reference rows 2–216 of Consolidated Data, which are exactly the Lopez rows (Witzgall, Wood and Saxman rows follow). Lopez monthly fees mix rental rates and CCRC monthly service fees that sit on top of an entrance fee (e.g., Wesley Manor $515/mo with a $179K entrance fee), so the low end understates rental-equivalent cost.
...

Sheet Good-Better-Best
A1: Service Offering Recommendations — Good / Better / Best by Function
A2: Three candidate offerings per function, derived from the Synthesis tab. "Good" = maintenance-free essentials (lightest viable package). "Better" = Base + Choice (market midpoint with a published add-on menu). "Best" = bundled villa experience (premium, CCRC-style inclusions). Indicative prices come from the sources cited; they are benchmarks, not a pricing recommendation.
A4: Function | B4: GOOD — Maintenance-Free Essentials | C4: BETTER — Base + Choice | D4: BEST — Bundled Villa Experience | E4: Why these three (evidence) | F4: Indicative pricing from sources | G4: Sources
A5: Transportation | B5: Scheduled group shuttle on the community's existing routes (shopping, banking, worship) within a 10-mile radius; medical appointments on set days. No personal transportation. | C5: Good, plus scheduled medical transportation within 10 miles on any weekday, and a published per-trip / per-mile rate for trips beyond 10 miles and for unscheduled rides. | D5: Better, plus a private on-demand car service allowance (e.g., a set number of personal trips per month) and after-hours / airport runs bookable through concierge. | E5: Scheduled transportation within ~10 miles is included at Provincial/Discovery (Wood), in the Witzgall model and at 5 of 6 Saxman communities; it is never itemized in the Lopez inventory. Personal/unscheduled transportation is à la carte everywhere it is mentioned (Hamilton Trace, Witzgall). | F5: Beyond-radius medical: $2.50–$4.00/mile or $25–$50/trip; private car $30–$60/hr; airport $75–$150/trip (Witzgall). | G5: Witzgall; Wood; Saxman; Lopez
A6: Life Enrichment / Campus Amenities | B6: Full access to the main community's calendar, fitness center, pool and common areas on the same basis as apartment residents. Outings and ticketed events pay-per-use. | C6: Good, plus a cottage-specific social program (neighborhood events, resident-led clubs, a cottage liaison) and a small annual outing credit. | D6: Better, plus concierge-booked excursions, specialty classes and personal training with a monthly enrichment credit, and priority registration for limited-seat events. | E6: Every source treats campus programming as an inclusion ("same as community residents" at both Wood operators; included in Witzgall; present at all 6 Saxman communities). Only excursions, materials and personal training are ever priced. | F6: Excursion tickets at cost $20–$100+; workshop materials $10–$30/class; personal training $60–$90/hr (Witzgall). | G6: Witzgall; Wood; Saxman; Lopez
A7: Culinary / Dining | B7: No meal plan in the base rent. Restaurant dining open to cottage residents at posted prices; a weekly continental breakfast or coffee social at the clubhouse. | C7: A monthly declining-balance dining credit (in the $300–$600 range) usable at any venue, with optional upgrade plans (10, 15 or 30 meals/month) priced separately and villa delivery at a per-meal fee. | D7: One chef-prepared meal per day (or 20–30 meals/month) included, plus daily continental breakfast, guest-meal allowance and villa delivery included; upgrade path to a full 3-meal plan. | E7: Dining is the most variable function: 17 of 53 Lopez mentions are optional or credit-based; Saxman ranges from none to 15 meals/month; Wood shows 1 vs 2 meals; Witzgall's base is breakfast, 1 meal/day or a $300 card. Full kitchens make a heavy plan unnecessary for most buyers. | F7: Declining-balance credits observed: $300/mo (Witzgall), $490 (Lake Forest Place), $540 (Friendship Village Dublin), $600 (The Stratford) (Lopez). 3-meal upgrade $600–$900/mo; guest meals $15–$25; delivery $5–$10/meal (Witzgall). | G7: Lopez; Witzgall; Wood; Saxman
A8: Housekeeping | B8: Not included. Housekeeping sold as a stand-alone monthly subscription or hourly service at a published rate; annual deep clean offered as an add-on. | C8: Bi-weekly light housekeeping included; weekly upgrade, deep cleaning and carpet cleaning at published prices. | D8: Weekly housekeeping with flat-linen service included, plus an annual spring deep clean; deep cleaning and organizing on request. | E8: Bi-weekly is the most common included cadence in Lopez and is the Witzgall base; monthly or optional at the light end (Robin Run, Garbry Ridge, Highgrove ~$240/mo, Integrated Senior Living none); weekly plus linen at the premium end (Five Star, Concordia OKC, Zarrow Pointe, Provincial/Discovery). | F8: Stand-alone: ~$240/mo (Saxman, Highgrove) or $25/hr (Lopez, Legacy Living Florence). Weekly upgrade over bi-weekly: +$150–$300/mo; deep clean $40–$60/hr (Witzgall). | G8: Lopez; Witzgall; Wood; Saxman
A9: Laundry & Linen | B9: In-unit washer/dryer (or hookups) provided; no laundry service. | C9: In-unit washer/dryer plus optional personal laundry and linen service priced per load or as a monthly package. | D9: In-unit washer/dryer plus weekly flat-linen service included; personal laundry package included or discounted. | E9: In-unit washer/dryer is near-universal in the Lopez inventory (a residence feature, not a service). Linen service rides with weekly housekeeping at the premium communities; laundry "available" at Trilogy campuses; Witzgall prices it as an add-on. | F9: Laundry & linen $20–$35/load or $100–$150/mo package (Witzgall). | G9: Lopez; Witzgall; Saxman
A10: Wellness / Fitness / Health | B10: Fitness center and pool access included; wellness programming on the community calendar. Clinical services referred to third parties. | C10: Good, plus a monthly on-site wellness clinic (blood pressure, weight, medication review) and an optional daily check-in call; home health and therapy providers coordinated on request at their rates. | D10: Better, plus an annual wellness/health-services allowance, a set number of free health-center days per year, and a resident wellness navigator who coordinates home care, therapy and medication management. | E10: Cottage-specific wellness is thin in Lopez (mostly campus access, occasional clinic/rehab "available", Twin Lakes annual allowance, Village at Germantown 10 free health-center days). Witzgall includes a monthly check-up and prices care services; Saxman shows wellness clinics at 5 of 6; Wood reported N/A. | F10: Medication management $300–$600/mo; PT/OT at copay; personal training $60–$90/hr (Witzgall). | G10: Lopez; Witzgall; Saxman; Wood
A11: Emergency / Safety / Security | B11: 24/7 emergency call system (pendant or pull cords) monitored by the main community; standard exterior lighting. | C11: Good, plus a wireless/mobile pendant that works across campus, 24-hour on-campus staff response and an optional daily check-in. | D11: Better, plus gated or controlled entry, 24-hour security/EMT presence, in-home smart sensors or fall detection, and priority response routing for the cottage neighborhood. | E11: Emergency response is the second most common Lopez inclusion (74 communities), included in the Witzgall base and at 5 of 6 Saxman communities. 24-hour security and gated entry appear at the CCRC/premium end (Twin Lakes, Trezevant, Kirby Pines, Holy Cross Village). Witzgall flags slower response times on spread footprints. | F11: Replacement pendant/fob $100–$150 one-time (Witzgall); no recurring charge observed in any source. | G11: Lopez; Witzgall; Saxman
A12: Maintenance (Interior / Exterior / Grounds) | B12: All exterior maintenance, lawn care, landscaping, snow and ice removal, plus repair of community-owned appliances and systems. Work-order response during business hours. | C12: Good, plus 24-hour emergency maintenance, routine interior preventive maintenance (filters, smoke detectors, seasonal checks) and a published handyman rate for resident-requested work. | D12: Better, plus included handyman hours each month, seasonal services (gutter, power-wash, window cleaning), and pre-scheduled interior refresh (paint/carpet) on a set cycle. | E12: Unanimous: maintenance is the single most common Lopez inclusion (102 communities), the Witzgall "core value proposition," and Saxman's "most consistently observed" service. It should never be optional; the tiers differ only in responsiveness and scope. | F12: Handyman appears only as an à la carte item (Cedarhurst, Saxman); no benchmark price in the sources. | G12: Lopez; Witzgall; Saxman
A13: Utilities / Taxes / Insurance | B13: Water, sewer and trash included; resident pays electric, gas, cable, internet and phone directly. | C13: All standard utilities (electric, gas, water, sewer, trash) plus basic cable and Wi-Fi bundled into the monthly fee; phone optional. | D13: Better, plus premium cable/streaming package, phone, and (for entry-fee structures) property taxes and building insurance carried by the community. | E13: Utilities are the most common Lopez line item (118 communities) and span exactly these three levels: water/sewer/trash only (Tabor Hills, Wilson Commons), all utilities plus cable/Wi-Fi (Traditions, Legacies, Oaks at Bartlett), and all utilities plus phone/cable/internet/taxes/insurance (Twin Lakes, Maple Knoll, Friendship Village Dublin). Witzgall bundles standard utilities and basic cable/Wi-Fi in rent; Saxman ranges from water-only to full bundles. | F13: Bundled inside the monthly fee in every source; no separate utility pricing reported. | G13: Lopez; Witzgall; Saxman
